Workbook

Sheet Marginal Impacts (7.3.1)
B1: 7.3.1
B2: EV | C2: FV | D2: HLV | E2: IV | F2: WV
A3: CORR | B3: =IF('Coefficients (7.3.1)'!C4<'Coefficients (7.3.1)'!B4,"F","R") -> R | C3: =IF('Coefficients (7.3.1)'!C17<'Coefficients (7.3.1)'!B17,"F","R") -> R | D3: =IF('Coefficients (7.3.1)'!C30<'Coefficients (7.3.1)'!B30,"F","R") -> R | E3: =IF('Coefficients (7.3.1)'!C43<'Coefficients (7.3.1)'!B43,"F","R") -> R | F3: =IF('Coefficients (7.3.1)'!C56<'Coefficients (7.3.1)'!B56,"F","R") -> R
B4: =IF('Coefficients (7.3.1)'!C6<'Coefficients (7.3.1)'!B6,"F","R") -> R | C4: =IF('Coefficients (7.3.1)'!C19<'Coefficients (7.3.1)'!B19,"F","R") -> R | D4: =IF('Coefficients (7.3.1)'!C32<'Coefficients (7.3.1)'!B32,"F","R") -> R | E4: =IF('Coefficients (7.3.1)'!C45<'Coefficients (7.3.1)'!B45,"F","R") -> R | F4: =IF('Coefficients (7.3.1)'!C58<'Coefficients (7.3.1)'!B58,"F","R") -> R
B5: =IF('Coefficients (7.3.1)'!C8<'Coefficients (7.3.1)'!B8,"F","R") -> R | C5: =IF('Coefficients (7.3.1)'!C21<'Coefficients (7.3.1)'!B21,"F","R") -> F | D5: =IF('Coefficients (7.3.1)'!C34<'Coefficients (7.3.1)'!B34,"F","R") -> F | E5: =IF('Coefficients (7.3.1)'!C47<'Coefficients (7.3.1)'!B47,"F","R") -> F | F5: =IF('Coefficients (7.3.1)'!C60<'Coefficients (7.3.1)'!B60,"F","R") -> R
B6: =IF('Coefficients (7.3.1)'!C10<'Coefficients (7.3.1)'!B10,"F","R") -> R | C6: =IF('Coefficients (7.3.1)'!C23<'Coefficients (7.3.1)'!B23,"F","R") -> R | D6: =IF('Coefficients (7.3.1)'!C36<'Coefficients (7.3.1)'!B36,"F","R") -> R | E6: =IF('Coefficients (7.3.1)'!C49<'Coefficients (7.3.1)'!B49,"F","R") -> R | F6: =IF('Coefficients (7.3.1)'!C62<'Coefficients (7.3.1)'!B62,"F","R") -> R
B7: =IF('Coefficients (7.3.1)'!C12<'Coefficients (7.3.1)'!B12,"F","R") -> F | C7: =IF('Coefficients (7.3.1)'!C25<'Coefficients (7.3.1)'!B25,"F","R") -> F | D7: =IF('Coefficients (7.3.1)'!C38<'Coefficients (7.3.1)'!B38,"F","R") -> F | E7: =IF('Coefficients (7.3.1)'!C51<'Coefficients (7.3.1)'!B51,"F","R") -> F | F7: =IF('Coefficients (7.3.1)'!C64<'Coefficients (7.3.1)'!B64,"F","R") -> F
A8: GOVEFF | B8: =IF('Coefficients (7.3.1)'!E4<'Coefficients (7.3.1)'!D4,"F","R") -> R | C8: =IF('Coefficients (7.3.1)'!E17<'Coefficients (7.3.1)'!D17,"F","R") -> R | D8: =IF('Coefficients (7.3.1)'!E30<'Coefficients (7.3.1)'!D30,"F","R") -> F | E8: =IF('Coefficients (7.3.1)'!E43<'Coefficients (7.3.1)'!D43,"F","R") -> R | F8: =IF('Coefficients (7.3.1)'!E56<'Coefficients (7.3.1)'!D56,"F","R") -> R
B9: =IF('Coefficients (7.3.1)'!E6<'Coefficients (7.3.1)'!D6,"F","R") -> F | C9: =IF('Coefficients (7.3.1)'!E19<'Coefficients (7.3.1)'!D19,"F","R") -> F | D9: =IF('Coefficients (7.3.1)'!E32<'Coefficients (7.3.1)'!D32,"F","R") -> F | E9: =IF('Coefficients (7.3.1)'!E45<'Coefficients (7.3.1)'!D45,"F","R") -> F | F9: =IF('Coefficients (7.3.1)'!E58<'Coefficients (7.3.1)'!D58,"F","R") -> F
B10: =IF('Coefficients (7.3.1)'!E8<'Coefficients (7.3.1)'!D8,"F","R") -> F | C10: =IF('Coefficients (7.3.1)'!E21<'Coefficients (7.3.1)'!D21,"F","R") -> F | D10: =IF('Coefficients (7.3.1)'!E34<'Coefficients (7.3.1)'!D34,"F","R") -> F | E10: =IF('Coefficients (7.3.1)'!E47<'Coefficients (7.3.1)'!D47,"F","R") -> F | F10: =IF('Coefficients (7.3.1)'!E60<'Coefficients (7.3.1)'!D60,"F","R") -> F
B11: =IF('Coefficients (7.3.1)'!E10<'Coefficients (7.3.1)'!D10,"F","R") -> R | C11: =IF('Coefficients (7.3.1)'!E23<'Coefficients (7.3.1)'!D23,"F","R") -> R | D11: =IF('Coefficients (7.3.1)'!E36<'Coefficients (7.3.1)'!D36,"F","R") -> R | E11: =IF('Coefficients (7.3.1)'!E49<'Coefficients (7.3.1)'!D49,"F","R") -> R | F11: =IF('Coefficients (7.3.1)'!E62<'Coefficients (7.3.1)'!D62,"F","R") -> R
B12: =IF('Coefficients (7.3.1)'!E12<'Coefficients (7.3.1)'!D12,"F","R") -> R | C12: =IF('Coefficients (7.3.1)'!E25<'Coefficients (7.3.1)'!D25,"F","R") -> R | D12: =IF('Coefficients (7.3.1)'!E38<'Coefficients (7.3.1)'!D38,"F","R") -> R | E12: =IF('Coefficients (7.3.1)'!E51<'Coefficients (7.3.1)'!D51,"F","R") -> R | F12: =IF('Coefficients (7.3.1)'!E64<'Coefficients (7.3.1)'!D64,"F","R") -> R
A13: POLST | B13: =IF('Coefficients (7.3.1)'!G4<'Coefficients (7.3.1)'!F4,"F","R") -> R | C13: =IF('Coefficients (7.3.1)'!G17<'Coefficients (7.3.1)'!F17,"F","R") -> R | D13: =IF('Coefficients (7.3.1)'!G30<'Coefficients (7.3.1)'!F30,"F","R") -> R | E13: =IF('Coefficients (7.3.1)'!G43<'Coefficients (7.3.1)'!F43,"F","R") -> R | F13: =IF('Coefficients (7.3.1)'!G56<'Coefficients (7.3.1)'!F56,"F","R") -> R
B14: =IF('Coefficients (7.3.1)'!G6<'Coefficients (7.3.1)'!F6,"F","R") -> R | C14: =IF('Coefficients (7.3.1)'!G19<'Coefficients (7.3.1)'!F19,"F","R") -> F | D14: =IF('Coefficients (7.3.1)'!G32<'Coefficients (7.3.1)'!F32,"F","R") -> F | E14: =IF('Coefficients (7.3.1)'!G45<'Coefficients (7.3.1)'!F45,"F","R") -> R | F14: =IF('Coefficients (7.3.1)'!G58<'Coefficients (7.3.1)'!F58,"F","R") -> R
B15: =IF('Coefficients (7.3.1)'!G8<'Coefficients (7.3.1)'!F8,"F","R") -> F | C15: =IF('Coefficients (7.3.1)'!G21<'Coefficients (7.3.1)'!F21,"F","R") -> F | D15: =IF('Coefficients (7.3.1)'!G34<'Coefficients (7.3.1)'!F34,"F","R") -> F | E15: =IF('Coefficients (7.3.1)'!G47<'Coefficients (7.3.1)'!F47,"F","R") -> F | F15: =IF('Coefficients (7.3.1)'!G60<'Coefficients (7.3.1)'!F60,"F","R") -> R
B16: =IF('Coefficients (7.3.1)'!G10<'Coefficients (7.3.1)'!F10,"F","R") -> R | C16: =IF('Coefficients (7.3.1)'!G23<'Coefficients (7.3.1)'!F23,"F","R") -> R | D16: =IF('Coefficients (7.3.1)'!G36<'Coefficients (7.3.1)'!F36,"F","R") -> R | E16: =IF('Coefficients (7.3.1)'!G49<'Coefficients (7.3.1)'!F49,"F","R") -> R | F16: =IF('Coefficients (7.3.1)'!G62<'Coefficients (7.3.1)'!F62,"F","R") -> R
B17: =IF('Coefficients (7.3.1)'!G12<'Coefficients (7.3.1)'!F12,"F","R") -> F | C17: =IF('Coefficients (7.3.1)'!G25<'Coefficients (7.3.1)'!F25,"F","R") -> F | D17: =IF('Coefficients (7.3.1)'!G38<'Coefficients (7.3.1)'!F38,"F","R") -> F | E17: =IF('Coefficients (7.3.1)'!G51<'Coefficients (7.3.1)'!F51,"F","R") -> F | F17: =IF('Coefficients (7.3.1)'!G64<'Coefficients (7.3.1)'!F64,"F","R") -> F
A18: REG | B18: =IF('Coefficients (7.3.1)'!I4<'Coefficients (7.3.1)'!H4,"F","R") -> R | C18: =IF('Coefficients (7.3.1)'!I17<'Coefficients (7.3.1)'!H17,"F","R") -> R | D18: =IF('Coefficients (7.3.1)'!I30<'Coefficients (7.3.1)'!H30,"F","R") -> R | E18: =IF('Coefficients (7.3.1)'!I43<'Coefficients (7.3.1)'!H43,"F","R") -> R | F18: =IF('Coefficients (7.3.1)'!I56<'Coefficients (7.3.1)'!H56,"F","R") -> R
B19: =IF('Coefficients (7.3.1)'!I6<'Coefficients (7.3.1)'!H6,"F","R") -> R | C19: =IF('Coefficients (7.3.1)'!I19<'Coefficients (7.3.1)'!H19,"F","R") -> F | D19: =IF('Coefficients (7.3.1)'!I32<'Coefficients (7.3.1)'!H32,"F","R") -> F | E19: =IF('Coefficients (7.3.1)'!I45<'Coefficients (7.3.1)'!H45,"F","R") -> R | F19: =IF('Coefficients (7.3.1)'!I58<'Coefficients (7.3.1)'!H58,"F","R") -> R
B20: =IF('Coefficients (7.3.1)'!I8<'Coefficients (7.3.1)'!H8,"F","R") -> R | C20: =IF('Coefficients (7.3.1)'!I21<'Coefficients (7.3.1)'!H21,"F","R") -> F | D20: =IF('Coefficients (7.3.1)'!I34<'Coefficients (7.3.1)'!H34,"F","R") -> F | E20: =IF('Coefficients (7.3.1)'!I47<'Coefficients (7.3.1)'!H47,"F","R") -> F | F20: =IF('Coefficients (7.3.1)'!I60<'Coefficients (7.3.1)'!H60,"F","R") -> F
B21: =IF('Coefficients (7.3.1)'!I10<'Coefficients (7.3.1)'!H10,"F","R") -> R | C21: =IF('Coefficients (7.3.1)'!I23<'Coefficients (7.3.1)'!H23,"F","R") -> R | D21: =IF('Coefficients (7.3.1)'!I36<'Coefficients (7.3.1)'!H36,"F","R") -> R | E21: =IF('Coefficients (7.3.1)'!I49<'Coefficients (7.3.1)'!H49,"F","R") -> R | F21: =IF('Coefficients (7.3.1)'!I62<'Coefficients (7.3.1)'!H62,"F","R") -> R
B22: =IF('Coefficients (7.3.1)'!I12<'Coefficients (7.3.1)'!H12,"F","R") -> F | C22: =IF('Coefficients (7.3.1)'!I25<'Coefficients (7.3.1)'!H25,"F","R") -> F | D22: =IF('Coefficients (7.3.1)'!I38<'Coefficients (7.3.1)'!H38,"F","R") -> F | E22: =IF('Coefficients (7.3.1)'!I51<'Coefficients (7.3.1)'!H51,"F","R") -> F | F22: =IF('Coefficients (7.3.1)'!I64<'Coefficients (7.3.1)'!H64,"F","R") -> F
A23: RULE | B23: =IF('Coefficients (7.3.1)'!K4<'Coefficients (7.3.1)'!J4,"F","R") -> R | C23: =IF('Coefficients (7.3.1)'!K17<'Coefficients (7.3.1)'!J17,"F","R") -> R | D23: =IF('Coefficients (7.3.1)'!K30<'Coefficients (7.3.1)'!J30,"F","R") -> R | E23: =IF('Coefficients (7.3.1)'!K43<'Coefficients (7.3.1)'!J43,"F","R") -> R | F23: =IF('Coefficients (7.3.1)'!K56<'Coefficients (7.3.1)'!J56,"F","R") -> R
B24: =IF('Coefficients (7.3.1)'!K6<'Coefficients (7.3.1)'!J6,"F","R") -> R | C24: =IF('Coefficients (7.3.1)'!K19<'Coefficients (7.3.1)'!J19,"F","R") -> F | D24: =IF('Coefficients (7.3.1)'!K32<'Coefficients (7.3.1)'!J32,"F","R") -> F | E24: =IF('Coefficients (7.3.1)'!K45<'Coefficients (7.3.1)'!J45,"F","R") -> R | F24: =IF('Coefficients (7.3.1)'!K58<'Coefficients (7.3.1)'!J58,"F","R") -> R
B25: =IF('Coefficients (7.3.1)'!K8<'Coefficients (7.3.1)'!J8,"F","R") -> F | C25: =IF('Coefficients (7.3.1)'!K21<'Coefficients (7.3.1)'!J21,"F","R") -> F | D25: =IF('Coefficients (7.3.1)'!K34<'Coefficients (7.3.1)'!J34,"F","R") -> F | E25: =IF('Coefficients (7.3.1)'!K47<'Coefficients (7.3.1)'!J47,"F","R") -> F | F25: =IF('Coefficients (7.3.1)'!K60<'Coefficients (7.3.1)'!J60,"F","R") -> F
B26: =IF('Coefficients (7.3.1)'!K10<'Coefficients (7.3.1)'!J10,"F","R") -> R | C26: =IF('Coefficients (7.3.1)'!K23<'Coefficients (7.3.1)'!J23,"F","R") -> F | D26: =IF('Coefficients (7.3.1)'!K36<'Coefficients (7.3.1)'!J36,"F","R") -> R | E26: =IF('Coefficients (7.3.1)'!K49<'Coefficients (7.3.1)'!J49,"F","R") -> R | F26: =IF('Coefficients (7.3.1)'!K62<'Coefficients (7.3.1)'!J62,"F","R") -> R
B27: =IF('Coefficients (7.3.1)'!K12<'Coefficients (7.3.1)'!J12,"F","R") -> R | C27: =IF('Coefficients (7.3.1)'!K25<'Coefficients (7.3.1)'!J25,"F","R") -> R | D27: =IF('Coefficients (7.3.1)'!K38<'Coefficients (7.3.1)'!J38,"F","R") -> R | E27: =IF('Coefficients (7.3.1)'!K51<'Coefficients (7.3.1)'!J51,"F","R") -> F | F27: =IF('Coefficients (7.3.1)'!K64<'Coefficients (7.3.1)'!J64,"F","R") -> F
A28: VOICE | B28: =IF('Coefficients (7.3.1)'!M4<'Coefficients (7.3.1)'!L4,"F","R") -> F | C28: =IF('Coefficients (7.3.1)'!M17<'Coefficients (7.3.1)'!L17,"F","R") -> R | D28: =IF('Coefficients (7.3.1)'!M30<'Coefficients (7.3.1)'!L30,"F","R") -> F | E28: =IF('Coefficients (7.3.1)'!M43<'Coefficients (7.3.1)'!L43,"F","R") -> F | F28: =IF('Coefficients (7.3.1)'!M56<'Coefficients (7.3.1)'!L56,"F","R") -> F
B29: =IF('Coefficients (7.3.1)'!M6<'Coefficients (7.3.1)'!L6,"F","R") -> R | C29: =IF('Coefficients (7.3.1)'!M19<'Coefficients (7.3.1)'!L19,"F","R") -> R | D29: =IF('Coefficients (7.3.1)'!M32<'Coefficients (7.3.1)'!L32,"F","R") -> F | E29: =IF('Coefficients (7.3.1)'!M45<'Coefficients (7.3.1)'!L45,"F","R") -> F | F29: =IF('Coefficients (7.3.1)'!M58<'Coefficients (7.3.1)'!L58,"F","R") -> F
B30: =IF('Coefficients (7.3.1)'!M8<'Coefficients (7.3.1)'!L8,"F","R") -> R | C30: =IF('Coefficients (7.3.1)'!M21<'Coefficients (7.3.1)'!L21,"F","R") -> R | D30: =IF('Coefficients (7.3.1)'!M34<'Coefficients (7.3.1)'!L34,"F","R") -> F | E30: =IF('Coefficients (7.3.1)'!M47<'Coefficients (7.3.1)'!L47,"F","R") -> R | F30: =IF('Coefficients (7.3.1)'!M60<'Coefficients (7.3.1)'!L60,"F","R") -> F
B31: =IF('Coefficients (7.3.1)'!M10<'Coefficients (7.3.1)'!L10,"F","R") -> R | C31: =IF('Coefficients (7.3.1)'!M23<'Coefficients (7.3.1)'!L23,"F","R") -> R | D31: =IF('Coefficients (7.3.1)'!M36<'Coefficients (7.3.1)'!L36,"F","R") -> R | E31: =IF('Coefficients (7.3.1)'!M49<'Coefficients (7.3.1)'!L49,"F","R") -> R | F31: =IF('Coefficients (7.3.1)'!M62<'Coefficients (7.3.1)'!L62,"F","R") -> R
B32: =IF('Coefficients (7.3.1)'!M12<'Coefficients (7.3.1)'!L12,"F","R") -> R | C32: =IF('Coefficients (7.3.1)'!M25<'Coefficients (7.3.1)'!L25,"F","R") -> F | D32: =IF('Coefficients (7.3.1)'!M38<'Coefficients (7.3.1)'!L38,"F","R") -> R | E32: =IF('Coefficients (7.3.1)'!M51<'Coefficients (7.3.1)'!L51,"F","R") -> R | F32: =IF('Coefficients (7.3.1)'!M64<'Coefficients (7.3.1)'!L64,"F","R") -> R
B35: Fall in Impact | C35: Rise in Impact
A36: Policy Stringency | B36: =(COUNTIF(B3:F3,"F")+COUNTIF(B8:F8,"F")+COUNTIF(B13:F13,"F")+COUNTIF(B18:F18,"F")+COUNTIF(B23:F23,"F")+COUNTIF(B28:F28,"F"))/30 -> 0.16666667 | C36: =(COUNTIF(B3:F3,"R")+COUNTIF(B8:F8,"R")+COUNTIF(B13:F13,"R")+COUNTIF(B18:F18,"R")+COUNTIF(B23:F23,"R")+COUNTIF(B28:F28,"R"))/30 -> 0.83333333
A37: Environmental Innovation | B37: =(COUNTIF(B4:F4,"F")+COUNTIF(B9:F9,"F")+COUNTIF(B14:F14,"F")+COUNTIF(B19:F19,"F")+COUNTIF(B24:F24,"F")+COUNTIF(B29:F29,"F"))/30 -> 0.46666667 | C37: =(COUNTIF(B4:F4,"R")+COUNTIF(B9:F9,"R")+COUNTIF(B14:F14,"R")+COUNTIF(B19:F19,"R")+COUNTIF(B24:F24,"R")+COUNTIF(B29:F29,"R"))/30 -> 0.53333333
A38: Foreign Direct Investment | B38: =(COUNTIF(B5:F5,"F")+COUNTIF(B10:F10,"F")+COUNTIF(B15:F15,"F")+COUNTIF(B20:F20,"F")+COUNTIF(B25:F25,"F")+COUNTIF(B30:F30,"F"))/30 -> 0.76666667 | C38: =(COUNTIF(B5:F5,"R")+COUNTIF(B10:F10,"R")+COUNTIF(B15:F15,"R")+COUNTIF(B20:F20,"R")+COUNTIF(B25:F25,"R")+COUNTIF(B30:F30,"R"))/30 -> 0.23333333
A39: Industrial Share | B39: =(COUNTIF(B6:F6,"F")+COUNTIF(B11:F11,"F")+COUNTIF(B16:F16,"F")+COUNTIF(B21:F21,"F")+COUNTIF(B26:F26,"F")+COUNTIF(B31:F31,"F"))/30 -> 0.033333333 | C39: =(COUNTIF(B6:F6,"R")+COUNTIF(B11:F11,"R")+COUNTIF(B16:F16,"R")+COUNTIF(B21:F21,"R")+COUNTIF(B26:F26,"R")+COUNTIF(B31:F31,"R"))/30 -> 0.96666667
A40: Energy Demand | B40: =(COUNTIF(B7:F7,"F")+COUNTIF(B12:F12,"F")+COUNTIF(B17:F17,"F")+COUNTIF(B22:F22,"F")+COUNTIF(B27:F27,"F")+COUNTIF(B32:F32,"F"))/30 -> 0.6 | C40: =(COUNTIF(B7:F7,"R")+COUNTIF(B12:F12,"R")+COUNTIF(B17:F17,"R")+COUNTIF(B22:F22,"R")+COUNTIF(B27:F27,"R")+COUNTIF(B32:F32,"R"))/30 -> 0.4

Sheet Marginal Impacts (7.2.1)
B1: 7.2.1
B2: EV | C2: FV | D2: HLV | E2: IV | F2: WV
A3: CORR | B3: =IF('Coefficients (7.2.1)'!C4<'Coefficients (7.2.1)'!B4,"F","R") -> R | C3: =IF('Coefficients (7.2.1)'!C17<'Coefficients (7.2.1)'!B17,"F","R") -> R | D3: =IF('Coefficients (7.2.1)'!C30<'Coefficients (7.2.1)'!B30,"F","R") -> F | E3: =IF('Coefficients (7.2.1)'!C43<'Coefficients (7.2.1)'!B43,"F","R") -> F | F3: =IF('Coefficients (7.2.1)'!C56<'Coefficients (7.2.1)'!B56,"F","R") -> R
B4: =IF('Coefficients (7.2.1)'!C6<'Coefficients (7.2.1)'!B6,"F","R") -> F | C4: =IF('Coefficients (7.2.1)'!C19<'Coefficients (7.2.1)'!B19,"F","R") -> F | D4: =IF('Coefficients (7.2.1)'!C32<'Coefficients (7.2.1)'!B32,"F","R") -> F | E4: =IF('Coefficients (7.2.1)'!C45<'Coefficients (7.2.1)'!B45,"F","R") -> F | F4: =IF('Coefficients (7.2.1)'!C58<'Coefficients (7.2.1)'!B58,"F","R") -> F
B5: =IF('Coefficients (7.2.1)'!C8<'Coefficients (7.2.1)'!B8,"F","R") -> F | C5: =IF('Coefficients (7.2.1)'!C21<'Coefficients (7.2.1)'!B21,"F","R") -> R | D5: =IF('Coefficients (7.2.1)'!C34<'Coefficients (7.2.1)'!B34,"F","R") -> R | E5: =IF('Coefficients (7.2.1)'!C47<'Coefficients (7.2.1)'!B47,"F","R") -> R | F5: =IF('Coefficients (7.2.1)'!C60<'Coefficients (7.2.1)'!B60,"F","R") -> R
B6: =IF('Coefficients (7.2.1)'!C10<'Coefficients (7.2.1)'!B10,"F","R") -> R | C6: =IF('Coefficients (7.2.1)'!C23<'Coefficients (7.2.1)'!B23,"F","R") -> R | D6: =IF('Coefficients (7.2.1)'!C36<'Coefficients (7.2.1)'!B36,"F","R") -> R | E6: =IF('Coefficients (7.2.1)'!C49<'Coefficients (7.2.1)'!B49,"F","R") -> R | F6: =IF('Coefficients (7.2.1)'!C62<'Coefficients (7.2.1)'!B62,"F","R") -> R
B7: =IF('Coefficients (7.2.1)'!C12<'Coefficients (7.2.1)'!B12,"F","R") -> F | C7: =IF('Coefficients (7.2.1)'!C25<'Coefficients (7.2.1)'!B25,"F","R") -> F | D7: =IF('Coefficients (7.2.1)'!C38<'Coefficients (7.2.1)'!B38,"F","R") -> F | E7: =IF('Coefficients (7.2.1)'!C51<'Coefficients (7.2.1)'!B51,"F","R") -> F | F7: =IF('Coefficients (7.2.1)'!C64<'Coefficients (7.2.1)'!B64,"F","R") -> F
A8: GOVEFF | B8: =IF('Coefficients (7.2.1)'!E4<'Coefficients (7.2.1)'!D4,"F","R") -> R | C8: =IF('Coefficients (7.2.1)'!E17<'Coefficients (7.2.1)'!D17,"F","R") -> R | D8: =IF('Coefficients (7.2.1)'!E30<'Coefficients (7.2.1)'!D30,"F","R") -> R | E8: =IF('Coefficients (7.2.1)'!E43<'Coefficients (7.2.1)'!D43,"F","R") -> R | F8: =IF('Coefficients (7.2.1)'!E56<'Coefficients (7.2.1)'!D56,"F","R") -> R
B9: =IF('Coefficients (7.2.1)'!E6<'Coefficients (7.2.1)'!D6,"F","R") -> R | C9: =IF('Coefficients (7.2.1)'!E19<'Coefficients (7.2.1)'!D19,"F","R") -> R | D9: =IF('Coefficients (7.2.1)'!E32<'Coefficients (7.2.1)'!D32,"F","R") -> R | E9: =IF('Coefficients (7.2.1)'!E45<'Coefficients (7.2.1)'!D45,"F","R") -> R | F9: =IF('Coefficients (7.2.1)'!E58<'Coefficients (7.2.1)'!D58,"F","R") -> R
B10: =IF('Coefficients (7.2.1)'!E8<'Coefficients (7.2.1)'!D8,"F","R") -> F | C10: =IF('Coefficients (7.2.1)'!E21<'Coefficients (7.2.1)'!D21,"F","R") -> R | D10: =IF('Coefficients (7.2.1)'!E34<'Coefficients (7.2.1)'!D34,"F","R") -> R | E10: =IF('Coefficients (7.2.1)'!E47<'Coefficients (7.2.1)'!D47,"F","R") -> R | F10: =IF('Coefficients (7.2.1)'!E60<'Coefficients (7.2.1)'!D60,"F","R") -> R
B11: =IF('Coefficients (7.2.1)'!E10<'Coefficients (7.2.1)'!D10,"F","R") -> F | C11: =IF('Coefficients (7.2.1)'!E23<'Coefficients (7.2.1)'!D23,"F","R") -> F | D11: =IF('Coefficients (7.2.1)'!E36<'Coefficients (7.2.1)'!D36,"F","R") -> F | E11: =IF('Coefficients (7.2.1)'!E49<'Coefficients (7.2.1)'!D49,"F","R") -> F | F11: =IF('Coefficients (7.2.1)'!E62<'Coefficients (7.2.1)'!D62,"F","R") -> F
B12: =IF('Coefficients (7.2.1)'!E12<'Coefficients (7.2.1)'!D12,"F","R") -> F | C12: =IF('Coefficients (7.2.1)'!E25<'Coefficients (7.2.1)'!D25,"F","R") -> F | D12: =IF('Coefficients (7.2.1)'!E38<'Coefficients (7.2.1)'!D38,"F","R") -> F | E12: =IF('Coefficients (7.2.1)'!E51<'Coefficients (7.2.1)'!D51,"F","R") -> F | F12: =IF('Coefficients (7.2.1)'!E64<'Coefficients (7.2.1)'!D64,"F","R") -> F
A13: POLST | B13: =IF('Coefficients (7.2.1)'!G4<'Coefficients (7.2.1)'!F4,"F","R") -> R | C13: =IF('Coefficients (7.2.1)'!G17<'Coefficients (7.2.1)'!F17,"F","R") -> F | D13: =IF('Coefficients (7.2.1)'!G30<'Coefficients (7.2.1)'!F30,"F","R") -> F | E13: =IF('Coefficients (7.2.1)'!G43<'Coefficients (7.2.1)'!F43,"F","R") -> F | F13: =IF('Coefficients (7.2.1)'!G56<'Coefficients (7.2.1)'!F56,"F","R") -> R
B14: =IF('Coefficients (7.2.1)'!G6<'Coefficients (7.2.1)'!F6,"F","R") -> F | C14: =IF('Coefficients (7.2.1)'!G19<'Coefficients (7.2.1)'!F19,"F","R") -> F | D14: =IF('Coefficients (7.2.1)'!G32<'Coefficients (7.2.1)'!F32,"F","R") -> F | E14: =IF('Coefficients (7.2.1)'!G45<'Coefficients (7.2.1)'!F45,"F","R") -> F | F14: =IF('Coefficients (7.2.1)'!G58<'Coefficients (7.2.1)'!F58,"F","R") -> F
B15: =IF('Coefficients (7.2.1)'!G8<'Coefficients (7.2.1)'!F8,"F","R") -> F | C15: =IF('Coefficients (7.2.1)'!G21<'Coefficients (7.2.1)'!F21,"F","R") -> R | D15: =IF('Coefficients (7.2.1)'!G34<'Coefficients (7.2.1)'!F34,"F","R") -> R | E15: =IF('Coefficients (7.2.1)'!G47<'Coefficients (7.2.1)'!F47,"F","R") -> R | F15: =IF('Coefficients (7.2.1)'!G60<'Coefficients (7.2.1)'!F60,"F","R") -> R
B16: =IF('Coefficients (7.2.1)'!G10<'Coefficients (7.2.1)'!F10,"F","R") -> R | C16: =IF('Coefficients (7.2.1)'!G23<'Coefficients (7.2.1)'!F23,"F","R") -> R | D16: =IF('Coefficients (7.2.1)'!G36<'Coefficients (7.2.1)'!F36,"F","R") -> R | E16: =IF('Coefficients (7.2.1)'!G49<'Coefficients (7.2.1)'!F49,"F","R") -> R | F16: =IF('Coefficients (7.2.1)'!G62<'Coefficients (7.2.1)'!F62,"F","R") -> R
B17: =IF('Coefficients (7.2.1)'!G12<'Coefficients (7.2.1)'!F12,"F","R") -> F | C17: =IF('Coefficients (7.2.1)'!G25<'Coefficients (7.2.1)'!F25,"F","R") -> F | D17: =IF('Coefficients (7.2.1)'!G38<'Coefficients (7.2.1)'!F38,"F","R") -> R | E17: =IF('Coefficients (7.2.1)'!G51<'Coefficients (7.2.1)'!F51,"F","R") -> F | F17: =IF('Coefficients (7.2.1)'!G64<'Coefficients (7.2.1)'!F64,"F","R") -> F
A18: REG | B18: =IF('Coefficients (7.2.1)'!I4<'Coefficients (7.2.1)'!H4,"F","R") -> R | C18: =IF('Coefficients (7.2.1)'!I17<'Coefficients (7.2.1)'!H17,"F","R") -> F | D18: =IF('Coefficients (7.2.1)'!I30<'Coefficients (7.2.1)'!H30,"F","R") -> R | E18: =IF('Coefficients (7.2.1)'!I43<'Coefficients (7.2.1)'!H43,"F","R") -> R | F18: =IF('Coefficients (7.2.1)'!I56<'Coefficients (7.2.1)'!H56,"F","R") -> R
B19: =IF('Coefficients (7.2.1)'!I6<'Coefficients (7.2.1)'!H6,"F","R") -> F | C19: =IF('Coefficients (7.2.1)'!I19<'Coefficients (7.2.1)'!H19,"F","R") -> F | D19: =IF('Coefficients (7.2.1)'!I32<'Coefficients (7.2.1)'!H32,"F","R") -> R | E19: =IF('Coefficients (7.2.1)'!I45<'Coefficients (7.2.1)'!H45,"F","R") -> F | F19: =IF('Coefficients (7.2.1)'!I58<'Coefficients (7.2.1)'!H58,"F","R") -> F
B20: =IF('Coefficients (7.2.1)'!I8<'Coefficients (7.2.1)'!H8,"F","R") -> F | C20: =IF('Coefficients (7.2.1)'!I21<'Coefficients (7.2.1)'!H21,"F","R") -> R | D20: =IF('Coefficients (7.2.1)'!I34<'Coefficients (7.2.1)'!H34,"F","R") -> R | E20: =IF('Coefficients (7.2.1)'!I47<'Coefficients (7.2.1)'!H47,"F","R") -> R | F20: =IF('Coefficients (7.2.1)'!I60<'Coefficients (7.2.1)'!H60,"F","R") -> R
B21: =IF('Coefficients (7.2.1)'!I10<'Coefficients (7.2.1)'!H10,"F","R") -> R | C21: =IF('Coefficients (7.2.1)'!I23<'Coefficients (7.2.1)'!H23,"F","R") -> R | D21: =IF('Coefficients (7.2.1)'!I36<'Coefficients (7.2.1)'!H36,"F","R") -> F | E21: =IF('Coefficients (7.2.1)'!I49<'Coefficients (7.2.1)'!H49,"F","R") -> F | F21: =IF('Coefficients (7.2.1)'!I62<'Coefficients (7.2.1)'!H62,"F","R") -> F
B22: =IF('Coefficients (7.2.1)'!I12<'Coefficients (7.2.1)'!H12,"F","R") -> F | C22: =IF('Coefficients (7.2.1)'!I25<'Coefficients (7.2.1)'!H25,"F","R") -> F | D22: =IF('Coefficients (7.2.1)'!I38<'Coefficients (7.2.1)'!H38,"F","R") -> F | E22: =IF('Coefficients (7.2.1)'!I51<'Coefficients (7.2.1)'!H51,"F","R") -> F | F22: =IF('Coefficients (7.2.1)'!I64<'Coefficients (7.2.1)'!H64,"F","R") -> F
A23: RULE | B23: =IF('Coefficients (7.2.1)'!K4<'Coefficients (7.2.1)'!J4,"F","R") -> R | C23: =IF('Coefficients (7.2.1)'!K17<'Coefficients (7.2.1)'!J17,"F","R") -> F | D23: =IF('Coefficients (7.2.1)'!K30<'Coefficients (7.2.1)'!J30,"F","R") -> F | E23: =IF('Coefficients (7.2.1)'!K43<'Coefficients (7.2.1)'!J43,"F","R") -> R | F23: =IF('Coefficients (7.2.1)'!K56<'Coefficients (7.2.1)'!J56,"F","R") -> F
B24: =IF('Coefficients (7.2.1)'!K6<'Coefficients (7.2.1)'!J6,"F","R") -> R | C24: =IF('Coefficients (7.2.1)'!K19<'Coefficients (7.2.1)'!J19,"F","R") -> R | D24: =IF('Coefficients (7.2.1)'!K32<'Coefficients (7.2.1)'!J32,"F","R") -> F | E24: =IF('Coefficients (7.2.1)'!K45<'Coefficients (7.2.1)'!J45,"F","R") -> F | F24: =IF('Coefficients (7.2.1)'!K58<'Coefficients (7.2.1)'!J58,"F","R") -> R
B25: =IF('Coefficients (7.2.1)'!K8<'Coefficients (7.2.1)'!J8,"F","R") -> F | C25: =IF('Coefficients (7.2.1)'!K21<'Coefficients (7.2.1)'!J21,"F","R") -> R | D25: =IF('Coefficients (7.2.1)'!K34<'Coefficients (7.2.1)'!J34,"F","R") -> R | E25: =IF('Coefficients (7.2.1)'!K47<'Coefficients (7.2.1)'!J47,"F","R") -> R | F25: =IF('Coefficients (7.2.1)'!K60<'Coefficients (7.2.1)'!J60,"F","R") -> R
B26: =IF('Coefficients (7.2.1)'!K10<'Coefficients (7.2.1)'!J10,"F","R") -> R | C26: =IF('Coefficients (7.2.1)'!K23<'Coefficients (7.2.1)'!J23,"F","R") -> R | D26: =IF('Coefficients (7.2.1)'!K36<'Coefficients (7.2.1)'!J36,"F","R") -> R | E26: =IF('Coefficients (7.2.1)'!K49<'Coefficients (7.2.1)'!J49,"F","R") -> R | F26: =IF('Coefficients (7.2.1)'!K62<'Coefficients (7.2.1)'!J62,"F","R") -> R
B27: =IF('Coefficients (7.2.1)'!K12<'Coefficients (7.2.1)'!J12,"F","R") -> F | C27: =IF('Coefficients (7.2.1)'!K25<'Coefficients (7.2.1)'!J25,"F","R") -> F | D27: =IF('Coefficients (7.2.1)'!K38<'Coefficients (7.2.1)'!J38,"F","R") -> R | E27: =IF('Coefficients (7.2.1)'!K51<'Coefficients (7.2.1)'!J51,"F","R") -> R | F27: =IF('Coefficients (7.2.1)'!K64<'Coefficients (7.2.1)'!J64,"F","R") -> F
A28: VOICE | B28: =IF('Coefficients (7.2.1)'!M4<'Coefficients (7.2.1)'!L4,"F","R") -> R | C28: =IF('Coefficients (7.2.1)'!M17<'Coefficients (7.2.1)'!L17,"F","R") -> F | D28: =IF('Coefficients (7.2.1)'!M30<'Coefficients (7.2.1)'!L30,"F","R") -> F | E28: =IF('Coefficients (7.2.1)'!M43<'Coefficients (7.2.1)'!L43,"F","R") -> R | F28: =IF('Coefficients (7.2.1)'!M56<'Coefficients (7.2.1)'!L56,"F","R") -> F
B29: =IF('Coefficients (7.2.1)'!M6<'Coefficients (7.2.1)'!L6,"F","R") -> R | C29: =IF('Coefficients (7.2.1)'!M19<'Coefficients (7.2.1)'!L19,"F","R") -> F | D29: =IF('Coefficients (7.2.1)'!M32<'Coefficients (7.2.1)'!L32,"F","R") -> F | E29: =IF('Coefficients (7.2.1)'!M45<'Coefficients (7.2.1)'!L45,"F","R") -> F | F29: =IF('Coefficients (7.2.1)'!M58<'Coefficients (7.2.1)'!L58,"F","R") -> R
B30: =IF('Coefficients (7.2.1)'!M8<'Coefficients (7.2.1)'!L8,"F","R") -> R | C30: =IF('Coefficients (7.2.1)'!M21<'Coefficients (7.2.1)'!L21,"F","R") -> R | D30: =IF('Coefficients (7.2.1)'!M34<'Coefficients (7.2.1)'!L34,"F","R") -> R | E30: =IF('Coefficients (7.2.1)'!M47<'Coefficients (7.2.1)'!L47,"F","R") -> R | F30: =IF('Coefficients (7.2.1)'!M60<'Coefficients (7.2.1)'!L60,"F","R") -> R
B31: =IF('Coefficients (7.2.1)'!M10<'Coefficients (7.2.1)'!L10,"F","R") -> R | C31: =IF('Coefficients (7.2.1)'!M23<'Coefficients (7.2.1)'!L23,"F","R") -> R | D31: =IF('Coefficients (7.2.1)'!M36<'Coefficients (7.2.1)'!L36,"F","R") -> R | E31: =IF('Coefficients (7.2.1)'!M49<'Coefficients (7.2.1)'!L49,"F","R") -> R | F31: =IF('Coefficients (7.2.1)'!M62<'Coefficients (7.2.1)'!L62,"F","R") -> R
B32: =IF('Coefficients (7.2.1)'!M12<'Coefficients (7.2.1)'!L12,"F","R") -> F | C32: =IF('Coefficients (7.2.1)'!M25<'Coefficients (7.2.1)'!L25,"F","R") -> F | D32: =IF('Coefficients (7.2.1)'!M38<'Coefficients (7.2.1)'!L38,"F","R") -> F | E32: =IF('Coefficients (7.2.1)'!M51<'Coefficients (7.2.1)'!L51,"F","R") -> F | F32: =IF('Coefficients (7.2.1)'!M64<'Coefficients (7.2.1)'!L64,"F","R") -> F
B35: Fall in Impact | C35: Rise in Impact
A36: Policy Stringency | B36: =(COUNTIF(B3:F3,"F")+COUNTIF(B8:F8,"F")+COUNTIF(B13:F13,"F")+COUNTIF(B18:F18,"F")+COUNTIF(B23:F23,"F")+COUNTIF(B28:F28,"F"))/30 -> 0.4 | C36: =(COUNTIF(B3:F3,"R")+COUNTIF(B8:F8,"R")+COUNTIF(B13:F13,"R")+COUNTIF(B18:F18,"R")+COUNTIF(B23:F23,"R")+COUNTIF(B28:F28,"R"))/30 -> 0.6
A37: Environmental Innovation | B37: =(COUNTIF(B4:F4,"F")+COUNTIF(B9:F9,"F")+COUNTIF(B14:F14,"F")+COUNTIF(B19:F19,"F")+COUNTIF(B24:F24,"F")+COUNTIF(B29:F29,"F"))/30 -> 0.63333333 | C37: =(COUNTIF(B4:F4,"R")+COUNTIF(B9:F9,"R")+COUNTIF(B14:F14,"R")+COUNTIF(B19:F19,"R")+COUNTIF(B24:F24,"R")+COUNTIF(B29:F29,"R"))/30 -> 0.36666667
A38: Financial Development | B38: =(COUNTIF(B5:F5,"F")+COUNTIF(B10:F10,"F")+COUNTIF(B15:F15,"F")+COUNTIF(B20:F20,"F")+COUNTIF(B25:F25,"F")+COUNTIF(B30:F30,"F"))/30 -> 0.16666667 | C38: =(COUNTIF(B5:F5,"R")+COUNTIF(B10:F10,"R")+COUNTIF(B15:F15,"R")+COUNTIF(B20:F20,"R")+COUNTIF(B25:F25,"R")+COUNTIF(B30:F30,"R"))/30 -> 0.83333333
A39: Net Energy Import | B39: =(COUNTIF(B6:F6,"F")+COUNTIF(B11:F11,"F")+COUNTIF(B16:F16,"F")+COUNTIF(B21:F21,"F")+COUNTIF(B26:F26,"F")+COUNTIF(B31:F31,"F"))/30 -> 0.26666667 | C39: =(COUNTIF(B6:F6,"R")+COUNTIF(B11:F11,"R")+COUNTIF(B16:F16,"R")+COUNTIF(B21:F21,"R")+COUNTIF(B26:F26,"R")+COUNTIF(B31:F31,"R"))/30 -> 0.73333333
A40: Low Carbon Trade | B40: =(COUNTIF(B7:F7,"F")+COUNTIF(B12:F12,"F")+COUNTIF(B17:F17,"F")+COUNTIF(B22:F22,"F")+COUNTIF(B27:F27,"F")+COUNTIF(B32:F32,"F"))/30 -> 0.9 | C40: =(COUNTIF(B7:F7,"R")+COUNTIF(B12:F12,"R")+COUNTIF(B17:F17,"R")+COUNTIF(B22:F22,"R")+COUNTIF(B27:F27,"R")+COUNTIF(B32:F32,"R"))/30 -> 0.1

Sheet Marginal Impacts (7.1.2)
B1: 7.1.2
B2: EV | C2: FV | D2: HLV | E2: IV | F2: WV
A3: CORR | B3: =IF('Coefficients (7.1.2)'!C4<'Coefficients (7.1.2)'!B4,"F","R") -> F | C3: =IF('Coefficients (7.1.2)'!C17<'Coefficients (7.1.2)'!B17,"F","R") -> F | D3: =IF('Coefficients (7.1.2)'!C30<'Coefficients (7.1.2)'!B30,"F","R") -> F | E3: =IF('Coefficients (7.1.2)'!C43<'Coefficients (7.1.2)'!B43,"F","R") -> F | F3: =IF('Coefficients (7.1.2)'!C56<'Coefficients (7.1.2)'!B56,"F","R") -> F
B4: =IF('Coefficients (7.1.2)'!C6<'Coefficients (7.1.2)'!B6,"F","R") -> R | C4: =IF('Coefficients (7.1.2)'!C19<'Coefficients (7.1.2)'!B19,"F","R") -> R | D4: =IF('Coefficients (7.1.2)'!C32<'Coefficients (7.1.2)'!B32,"F","R") -> R | E4: =IF('Coefficients (7.1.2)'!C45<'Coefficients (7.1.2)'!B45,"F","R") -> R | F4: =IF('Coefficients (7.1.2)'!C58<'Coefficients (7.1.2)'!B58,"F","R") -> F
B5: =IF('Coefficients (7.1.2)'!C8<'Coefficients (7.1.2)'!B8,"F","R") -> F | C5: =IF('Coefficients (7.1.2)'!C21<'Coefficients (7.1.2)'!B21,"F","R") -> R | D5: =IF('Coefficients (7.1.2)'!C34<'Coefficients (7.1.2)'!B34,"F","R") -> R | E5: =IF('Coefficients (7.1.2)'!C47<'Coefficients (7.1.2)'!B47,"F","R") -> F | F5: =IF('Coefficients (7.1.2)'!C60<'Coefficients (7.1.2)'!B60,"F","R") -> R
B6: =IF('Coefficients (7.1.2)'!C10<'Coefficients (7.1.2)'!B10,"F","R") -> F | C6: =IF('Coefficients (7.1.2)'!C23<'Coefficients (7.1.2)'!B23,"F","R") -> F | D6: =IF('Coefficients (7.1.2)'!C36<'Coefficients (7.1.2)'!B36,"F","R") -> F | E6: =IF('Coefficients (7.1.2)'!C49<'Coefficients (7.1.2)'!B49,"F","R") -> F | F6: =IF('Coefficients (7.1.2)'!C62<'Coefficients (7.1.2)'!B62,"F","R") -> F
B7: =IF('Coefficients (7.1.2)'!C12<'Coefficients (7.1.2)'!B12,"F","R") -> F | C7: =IF('Coefficients (7.1.2)'!C25<'Coefficients (7.1.2)'!B25,"F","R") -> F | D7: =IF('Coefficients (7.1.2)'!C38<'Coefficients (7.1.2)'!B38,"F","R") -> F | E7: =IF('Coefficients (7.1.2)'!C51<'Coefficients (7.1.2)'!B51,"F","R") -> F | F7: =IF('Coefficients (7.1.2)'!C64<'Coefficients (7.1.2)'!B64,"F","R") -> F
A8: GOVEFF | B8: =IF('Coefficients (7.1.2)'!E4<'Coefficients (7.1.2)'!D4,"F","R") -> F | C8: =IF('Coefficients (7.1.2)'!E17<'Coefficients (7.1.2)'!D17,"F","R") -> R | D8: =IF('Coefficients (7.1.2)'!E30<'Coefficients (7.1.2)'!D30,"F","R") -> F | E8: =IF('Coefficients (7.1.2)'!E43<'Coefficients (7.1.2)'!D43,"F","R") -> F | F8: =IF('Coefficients (7.1.2)'!E56<'Coefficients (7.1.2)'!D56,"F","R") -> F
B9: =IF('Coefficients (7.1.2)'!E6<'Coefficients (7.1.2)'!D6,"F","R") -> R | C9: =IF('Coefficients (7.1.2)'!E19<'Coefficients (7.1.2)'!D19,"F","R") -> R | D9: =IF('Coefficients (7.1.2)'!E32<'Coefficients (7.1.2)'!D32,"F","R") -> R | E9: =IF('Coefficients (7.1.2)'!E45<'Coefficients (7.1.2)'!D45,"F","R") -> R | F9: =IF('Coefficients (7.1.2)'!E58<'Coefficients (7.1.2)'!D58,"F","R") -> F
B10: =IF('Coefficients (7.1.2)'!E8<'Coefficients (7.1.2)'!D8,"F","R") -> F | C10: =IF('Coefficients (7.1.2)'!E21<'Coefficients (7.1.2)'!D21,"F","R") -> F | D10: =IF('Coefficients (7.1.2)'!E34<'Coefficients (7.1.2)'!D34,"F","R") -> F | E10: =IF('Coefficients (7.1.2)'!E47<'Coefficients (7.1.2)'!D47,"F","R") -> R | F10: =IF('Coefficients (7.1.2)'!E60<'Coefficients (7.1.2)'!D60,"F","R") -> F
B11: =IF('Coefficients (7.1.2)'!E10<'Coefficients (7.1.2)'!D10,"F","R") -> F | C11: =IF('Coefficients (7.1.2)'!E23<'Coefficients (7.1.2)'!D23,"F","R") -> F | D11: =IF('Coefficients (7.1.2)'!E36<'Coefficients (7.1.2)'!D36,"F","R") -> F | E11: =IF('Coefficients (7.1.2)'!E49<'Coefficients (7.1.2)'!D49,"F","R") -> F | F11: =IF('Coefficients (7.1.2)'!E62<'Coefficients (7.1.2)'!D62,"F","R") -> R
B12: =IF('Coefficients (7.1.2)'!E12<'Coefficients (7.1.2)'!D12,"F","R") -> R | C12: =IF('Coefficients (7.1.2)'!E25<'Coefficients (7.1.2)'!D25,"F","R") -> F | D12: =IF('Coefficients (7.1.2)'!E38<'Coefficients (7.1.2)'!D38,"F","R") -> F | E12: =IF('Coefficients (7.1.2)'!E51<'Coefficients (7.1.2)'!D51,"F","R") -> F | F12: =IF('Coefficients (7.1.2)'!E64<'Coefficients (7.1.2)'!D64,"F","R") -> R
A13: POLST | B13: =IF('Coefficients (7.1.2)'!G4<'Coefficients (7.1.2)'!F4,"F","R") -> F | C13: =IF('Coefficients (7.1.2)'!G17<'Coefficients (7.1.2)'!F17,"F","R") -> F | D13: =IF('Coefficients (7.1.2)'!G30<'Coefficients (7.1.2)'!F30,"F","R") -> F | E13: =IF('Coefficients (7.1.2)'!G43<'Coefficients (7.1.2)'!F43,"F","R") -> R | F13: =IF('Coefficients (7.1.2)'!G56<'Coefficients (7.1.2)'!F56,"F","R") -> F
B14: =IF('Coefficients (7.1.2)'!G6<'Coefficients (7.1.2)'!F6,"F","R") -> R | C14: =IF('Coefficients (7.1.2)'!G19<'Coefficients (7.1.2)'!F19,"F","R") -> R | D14: =IF('Coefficients (7.1.2)'!G32<'Coefficients (7.1.2)'!F32,"F","R") -> R | E14: =IF('Coefficients (7.1.2)'!G45<'Coefficients (7.1.2)'!F45,"F","R") -> R | F14: =IF('Coefficients (7.1.2)'!G58<'Coefficients (7.1.2)'!F58,"F","R") -> R
B15: =IF('Coefficients (7.1.2)'!G8<'Coefficients (7.1.2)'!F8,"F","R") -> F | C15: =IF('Coefficients (7.1.2)'!G21<'Coefficients (7.1.2)'!F21,"F","R") -> F | D15: =IF('Coefficients (7.1.2)'!G34<'Coefficients (7.1.2)'!F34,"F","R") -> F | E15: =IF('Coefficients (7.1.2)'!G47<'Coefficients (7.1.2)'!F47,"F","R") -> R | F15: =IF('Coefficients (7.1.2)'!G60<'Coefficients (7.1.2)'!F60,"F","R") -> F
B16: =IF('Coefficients (7.1.2)'!G10<'Coefficients (7.1.2)'!F10,"F","R") -> F | C16: =IF('Coefficients (7.1.2)'!G23<'Coefficients (7.1.2)'!F23,"F","R") -> F | D16: =IF('Coefficients (7.1.2)'!G36<'Coefficients (7.1.2)'!F36,"F","R") -> F | E16: =IF('Coefficients (7.1.2)'!G49<'Coefficients (7.1.2)'!F49,"F","R") -> F | F16: =IF('Coefficients (7.1.2)'!G62<'Coefficients (7.1.2)'!F62,"F","R") -> F
B17: =IF('Coefficients (7.1.2)'!G12<'Coefficients (7.1.2)'!F12,"F","R") -> F | C17: =IF('Coefficients (7.1.2)'!G25<'Coefficients (7.1.2)'!F25,"F","R") -> F | D17: =IF('Coefficients (7.1.2)'!G38<'Coefficients (7.1.2)'!F38,"F","R") -> F | E17: =IF('Coefficients (7.1.2)'!G51<'Coefficients (7.1.2)'!F51,"F","R") -> F | F17: =IF('Coefficients (7.1.2)'!G64<'Coefficients (7.1.2)'!F64,"F","R") -> R
A18: REG | B18: =IF('Coefficients (7.1.2)'!I4<'Coefficients (7.1.2)'!H4,"F","R") -> F | C18: =IF('Coefficients (7.1.2)'!I17<'Coefficients (7.1.2)'!H17,"F","R") -> R | D18: =IF('Coefficients (7.1.2)'!I30<'Coefficients (7.1.2)'!H30,"F","R") -> F | E18: =IF('Coefficients (7.1.2)'!I43<'Coefficients (7.1.2)'!H43,"F","R") -> F | F18: =IF('Coefficients (7.1.2)'!I56<'Coefficients (7.1.2)'!H56,"F","R") -> F
B19: =IF('Coefficients (7.1.2)'!I6<'Coefficients (7.1.2)'!H6,"F","R") -> R | C19: =IF('Coefficients (7.1.2)'!I19<'Coefficients (7.1.2)'!H19,"F","R") -> R | D19: =IF('Coefficients (7.1.2)'!I32<'Coefficients (7.1.2)'!H32,"F","R") -> R | E19: =IF('Coefficients (7.1.2)'!I45<'Coefficients (7.1.2)'!H45,"F","R") -> R | F19: =IF('Coefficients (7.1.2)'!I58<'Coefficients (7.1.2)'!H58,"F","R") -> F
B20: =IF('Coefficients (7.1.2)'!I8<'Coefficients (7.1.2)'!H8,"F","R") -> F | C20: =IF('Coefficients (7.1.2)'!I21<'Coefficients (7.1.2)'!H21,"F","R") -> F | D20: =IF('Coefficients (7.1.2)'!I34<'Coefficients (7.1.2)'!H34,"F","R") -> F | E20: =IF('Coefficients (7.1.2)'!I47<'Coefficients (7.1.2)'!H47,"F","R") -> F | F20: =IF('Coefficients (7.1.2)'!I60<'Coefficients (7.1.2)'!H60,"F","R") -> F
B21: =IF('Coefficients (7.1.2)'!I10<'Coefficients (7.1.2)'!H10,"F","R") -> F | C21: =IF('Coefficients (7.1.2)'!I23<'Coefficients (7.1.2)'!H23,"F","R") -> F | D21: =IF('Coefficients (7.1.2)'!I36<'Coefficients (7.1.2)'!H36,"F","R") -> F | E21: =IF('Coefficients (7.1.2)'!I49<'Coefficients (7.1.2)'!H49,"F","R") -> F | F21: =IF('Coefficients (7.1.2)'!I62<'Coefficients (7.1.2)'!H62,"F","R") -> F
B22: =IF('Coefficients (7.1.2)'!I12<'Coefficients (7.1.2)'!H12,"F","R") -> F | C22: =IF('Coefficients (7.1.2)'!I25<'Coefficients (7.1.2)'!H25,"F","R") -> F | D22: =IF('Coefficients (7.1.2)'!I38<'Coefficients (7.1.2)'!H38,"F","R") -> F | E22: =IF('Coefficients (7.1.2)'!I51<'Coefficients (7.1.2)'!H51,"F","R") -> F | F22: =IF('Coefficients (7.1.2)'!I64<'Coefficients (7.1.2)'!H64,"F","R") -> F
A23: RULE | B23: =IF('Coefficients (7.1.2)'!K4<'Coefficients (7.1.2)'!J4,"F","R") -> F | C23: =IF('Coefficients (7.1.2)'!K17<'Coefficients (7.1.2)'!J17,"F","R") -> F | D23: =IF('Coefficients (7.1.2)'!K30<'Coefficients (7.1.2)'!J30,"F","R") -> F | E23: =IF('Coefficients (7.1.2)'!K43<'Coefficients (7.1.2)'!J43,"F","R") -> F | F23: =IF('Coefficients (7.1.2)'!K56<'Coefficients (7.1.2)'!J56,"F","R") -> F
B24: =IF('Coefficients (7.1.2)'!K6<'Coefficients (7.1.2)'!J6,"F","R") -> R | C24: =IF('Coefficients (7.1.2)'!K19<'Coefficients (7.1.2)'!J19,"F","R") -> R | D24: =IF('Coefficients (7.1.2)'!K32<'Coefficients (7.1.2)'!J32,"F","R") -> R | E24: =IF('Coefficients (7.1.2)'!K45<'Coefficients (7.1.2)'!J45,"F","R") -> R | F24: =IF('Coefficients (7.1.2)'!K58<'Coefficients (7.1.2)'!J58,"F","R") -> F
B25: =IF('Coefficients (7.1.2)'!K8<'Coefficients (7.1.2)'!J8,"F","R") -> F | C25: =IF('Coefficients (7.1.2)'!K21<'Coefficients (7.1.2)'!J21,"F","R") -> R | D25: =IF('Coefficients (7.1.2)'!K34<'Coefficients (7.1.2)'!J34,"F","R") -> F | E25: =IF('Coefficients (7.1.2)'!K47<'Coefficients (7.1.2)'!J47,"F","R") -> F | F25: =IF('Coefficients (7.1.2)'!K60<'Coefficients (7.1.2)'!J60,"F","R") -> R
B26: =IF('Coefficients (7.1.2)'!K10<'Coefficients (7.1.2)'!J10,"F","R") -> F | C26: =IF('Coefficients (7.1.2)'!K23<'Coefficients (7.1.2)'!J23,"F","R") -> F | D26: =IF('Coefficients (7.1.2)'!K36<'Coefficients (7.1.2)'!J36,"F","R") -> F | E26: =IF('Coefficients (7.1.2)'!K49<'Coefficients (7.1.2)'!J49,"F","R") -> F | F26: =IF('Coefficients (7.1.2)'!K62<'Coefficients (7.1.2)'!J62,"F","R") -> F
B27: =IF('Coefficients (7.1.2)'!K12<'Coefficients (7.1.2)'!J12,"F","R") -> F | C27: =IF('Coefficients (7.1.2)'!K25<'Coefficients (7.1.2)'!J25,"F","R") -> F | D27: =IF('Coefficients (7.1.2)'!K38<'Coefficients (7.1.2)'!J38,"F","R") -> R | E27: =IF('Coefficients (7.1.2)'!K51<'Coefficients (7.1.2)'!J51,"F","R") -> F | F27: =IF('Coefficients (7.1.2)'!K64<'Coefficients (7.1.2)'!J64,"F","R") -> F
A28: VOICE | B28: =IF('Coefficients (7.1.2)'!M4<'Coefficients (7.1.2)'!L4,"F","R") -> F | C28: =IF('Coefficients (7.1.2)'!M17<'Coefficients (7.1.2)'!L17,"F","R") -> F | D28: =IF('Coefficients (7.1.2)'!M30<'Coefficients (7.1.2)'!L30,"F","R") -> F | E28: =IF('Coefficients (7.1.2)'!M43<'Coefficients (7.1.2)'!L43,"F","R") -> F | F28: =IF('Coefficients (7.1.2)'!M56<'Coefficients (7.1.2)'!L56,"F","R") -> F
B29: =IF('Coefficients (7.1.2)'!M6<'Coefficients (7.1.2)'!L6,"F","R") -> R | C29: =IF('Coefficients (7.1.2)'!M19<'Coefficients (7.1.2)'!L19,"F","R") -> R | D29: =IF('Coefficients (7.1.2)'!M32<'Coefficients (7.1.2)'!L32,"F","R") -> R | E29: =IF('Coefficients (7.1.2)'!M45<'Coefficients (7.1.2)'!L45,"F","R") -> R | F29: =IF('Coefficients (7.1.2)'!M58<'Coefficients (7.1.2)'!L58,"F","R") -> R
B30: =IF('Coefficients (7.1.2)'!M8<'Coefficients (7.1.2)'!L8,"F","R") -> F | C30: =IF('Coefficients (7.1.2)'!M21<'Coefficients (7.1.2)'!L21,"F","R") -> R | D30: =IF('Coefficients (7.1.2)'!M34<'Coefficients (7.1.2)'!L34,"F","R") -> R | E30: =IF('Coefficients (7.1.2)'!M47<'Coefficients (7.1.2)'!L47,"F","R") -> R | F30: =IF('Coefficients (7.1.2)'!M60<'Coefficients (7.1.2)'!L60,"F","R") -> F
B31: =IF('Coefficients (7.1.2)'!M10<'Coefficients (7.1.2)'!L10,"F","R") -> R | C31: =IF('Coefficients (7.1.2)'!M23<'Coefficients (7.1.2)'!L23,"F","R") -> F | D31: =IF('Coefficients (7.1.2)'!M36<'Coefficients (7.1.2)'!L36,"F","R") -> R | E31: =IF('Coefficients (7.1.2)'!M49<'Coefficients (7.1.2)'!L49,"F","R") -> R | F31: =IF('Coefficients (7.1.2)'!M62<'Coefficients (7.1.2)'!L62,"F","R") -> R
B32: =IF('Coefficients (7.1.2)'!M12<'Coefficients (7.1.2)'!L12,"F","R") -> F | C32: =IF('Coefficients (7.1.2)'!M25<'Coefficients (7.1.2)'!L25,"F","R") -> R | D32: =IF('Coefficients (7.1.2)'!M38<'Coefficients (7.1.2)'!L38,"F","R") -> F | E32: =IF('Coefficients (7.1.2)'!M51<'Coefficients (7.1.2)'!L51,"F","R") -> R | F32: =IF('Coefficients (7.1.2)'!M64<'Coefficients (7.1.2)'!L64,"F","R") -> R
B35: Fall in Impact | C35: Rise in Impact
A36: Renewable Electricity Generation | B36: =(COUNTIF(B3:F3,"F")+COUNTIF(B8:F8,"F")+COUNTIF(B13:F13,"F")+COUNTIF(B18:F18,"F")+COUNTIF(B23:F23,"F")+COUNTIF(B28:F28,"F"))/30 -> 0.9 | C36: =(COUNTIF(B3:F3,"R")+COUNTIF(B8:F8,"R")+COUNTIF(B13:F13,"R")+COUNTIF(B18:F18,"R")+COUNTIF(B23:F23,"R")+COUNTIF(B28:F28,"R"))/30 -> 0.1
A37: Financial Access | B37: =(COUNTIF(B4:F4,"F")+COUNTIF(B9:F9,"F")+COUNTIF(B14:F14,"F")+COUNTIF(B19:F19,"F")+COUNTIF(B24:F24,"F")+COUNTIF(B29:F29,"F"))/30 -> 0.13333333 | C37: =(COUNTIF(B4:F4,"R")+COUNTIF(B9:F9,"R")+COUNTIF(B14:F14,"R")+COUNTIF(B19:F19,"R")+COUNTIF(B24:F24,"R")+COUNTIF(B29:F29,"R"))/30 -> 0.86666667
A38: Policy Stringency | B38: =(COUNTIF(B5:F5,"F")+COUNTIF(B10:F10,"F")+COUNTIF(B15:F15,"F")+COUNTIF(B20:F20,"F")+COUNTIF(B25:F25,"F")+COUNTIF(B30:F30,"F"))/30 -> 0.66666667 | C38: =(COUNTIF(B5:F5,"R")+COUNTIF(B10:F10,"R")+COUNTIF(B15:F15,"R")+COUNTIF(B20:F20,"R")+COUNTIF(B25:F25,"R")+COUNTIF(B30:F30,"R"))/30 -> 0.33333333
A39: Per Capita Income | B39: =(COUNTIF(B6:F6,"F")+COUNTIF(B11:F11,"F")+COUNTIF(B16:F16,"F")+COUNTIF(B21:F21,"F")+COUNTIF(B26:F26,"F")+COUNTIF(B31:F31,"F"))/30 -> 0.83333333 | C39: =(COUNTIF(B6:F6,"R")+COUNTIF(B11:F11,"R")+COUNTIF(B16:F16,"R")+COUNTIF(B21:F21,"R")+COUNTIF(B26:F26,"R")+COUNTIF(B31:F31,"R"))/30 -> 0.16666667
A40: Urban Population Growth | B40: =(COUNTIF(B7:F7,"F")+COUNTIF(B12:F12,"F")+COUNTIF(B17:F17,"F")+COUNTIF(B22:F22,"F")+COUNTIF(B27:F27,"F")+COUNTIF(B32:F32,"F"))/30 -> 0.76666667 | C40: =(COUNTIF(B7:F7,"R")+COUNTIF(B12:F12,"R")+COUNTIF(B17:F17,"R")+COUNTIF(B22:F22,"R")+COUNTIF(B27:F27,"R")+COUNTIF(B32:F32,"R"))/30 -> 0.23333333

Sheet Marginal Impacts (7.1.1)
B1: 7.1.1
B2: EV | C2: FV | D2: HLV | E2: IV | F2: WV
A3: CORR | B3: =IF('Coefficients (7.1.1)'!C4<'Coefficients (7.1.1)'!B4,"F","R") -> F | C3: =IF('Coefficients (7.1.1)'!C17<'Coefficients (7.1.1)'!B17,"F","R") -> F | D3: =IF('Coefficients (7.1.1)'!C30<'Coefficients (7.1.1)'!B30,"F","R") -> F | E3: =IF('Coefficients (7.1.1)'!C43<'Coefficients (7.1.1)'!B43,"F","R") -> F | F3: =IF('Coefficients (7.1.1)'!C56<'Coefficients (7.1.1)'!B56,"F","R") -> F
B4: =IF('Coefficients (7.1.1)'!C6<'Coefficients (7.1.1)'!B6,"F","R") -> F | C4: =IF('Coefficients (7.1.1)'!C19<'Coefficients (7.1.1)'!B19,"F","R") -> R | D4: =IF('Coefficients (7.1.1)'!C32<'Coefficients (7.1.1)'!B32,"F","R") -> R | E4: =IF('Coefficients (7.1.1)'!C45<'Coefficients (7.1.1)'!B45,"F","R") -> F | F4: =IF('Coefficients (7.1.1)'!C58<'Coefficients (7.1.1)'!B58,"F","R") -> F
B5: =IF('Coefficients (7.1.1)'!C8<'Coefficients (7.1.1)'!B8,"F","R") -> R | C5: =IF('Coefficients (7.1.1)'!C21<'Coefficients (7.1.1)'!B21,"F","R") -> F | D5: =IF('Coefficients (7.1.1)'!C34<'Coefficients (7.1.1)'!B34,"F","R") -> R | E5: =IF('Coefficients (7.1.1)'!C47<'Coefficients (7.1.1)'!B47,"F","R") -> R | F5: =IF('Coefficients (7.1.1)'!C60<'Coefficients (7.1.1)'!B60,"F","R") -> R
B6: =IF('Coefficients (7.1.1)'!C10<'Coefficients (7.1.1)'!B10,"F","R") -> R | C6: =IF('Coefficients (7.1.1)'!C23<'Coefficients (7.1.1)'!B23,"F","R") -> R | D6: =IF('Coefficients (7.1.1)'!C36<'Coefficients (7.1.1)'!B36,"F","R") -> F | E6: =IF('Coefficients (7.1.1)'!C49<'Coefficients (7.1.1)'!B49,"F","R") -> R | F6: =IF('Coefficients (7.1.1)'!C62<'Coefficients (7.1.1)'!B62,"F","R") -> R
B7: =IF('Coefficients (7.1.1)'!C12<'Coefficients (7.1.1)'!B12,"F","R") -> F | C7: =IF('Coefficients (7.1.1)'!C25<'Coefficients (7.1.1)'!B25,"F","R") -> R | D7: =IF('Coefficients (7.1.1)'!C38<'Coefficients (7.1.1)'!B38,"F","R") -> F | E7: =IF('Coefficients (7.1.1)'!C51<'Coefficients (7.1.1)'!B51,"F","R") -> F | F7: =IF('Coefficients (7.1.1)'!C64<'Coefficients (7.1.1)'!B64,"F","R") -> F
A8: GOVEFF | B8: =IF('Coefficients (7.1.1)'!E4<'Coefficients (7.1.1)'!D4,"F","R") -> F | C8: =IF('Coefficients (7.1.1)'!E17<'Coefficients (7.1.1)'!D17,"F","R") -> R | D8: =IF('Coefficients (7.1.1)'!E30<'Coefficients (7.1.1)'!D30,"F","R") -> R | E8: =IF('Coefficients (7.1.1)'!E43<'Coefficients (7.1.1)'!D43,"F","R") -> F | F8: =IF('Coefficients (7.1.1)'!E56<'Coefficients (7.1.1)'!D56,"F","R") -> F
B9: =IF('Coefficients (7.1.1)'!E6<'Coefficients (7.1.1)'!D6,"F","R") -> R | C9: =IF('Coefficients (7.1.1)'!E19<'Coefficients (7.1.1)'!D19,"F","R") -> R | D9: =IF('Coefficients (7.1.1)'!E32<'Coefficients (7.1.1)'!D32,"F","R") -> R | E9: =IF('Coefficients (7.1.1)'!E45<'Coefficients (7.1.1)'!D45,"F","R") -> F | F9: =IF('Coefficients (7.1.1)'!E58<'Coefficients (7.1.1)'!D58,"F","R") -> R
B10: =IF('Coefficients (7.1.1)'!E8<'Coefficients (7.1.1)'!D8,"F","R") -> F | C10: =IF('Coefficients (7.1.1)'!E21<'Coefficients (7.1.1)'!D21,"F","R") -> F | D10: =IF('Coefficients (7.1.1)'!E34<'Coefficients (7.1.1)'!D34,"F","R") -> R | E10: =IF('Coefficients (7.1.1)'!E47<'Coefficients (7.1.1)'!D47,"F","R") -> R | F10: =IF('Coefficients (7.1.1)'!E60<'Coefficients (7.1.1)'!D60,"F","R") -> R
B11: =IF('Coefficients (7.1.1)'!E10<'Coefficients (7.1.1)'!D10,"F","R") -> R | C11: =IF('Coefficients (7.1.1)'!E23<'Coefficients (7.1.1)'!D23,"F","R") -> R | D11: =IF('Coefficients (7.1.1)'!E36<'Coefficients (7.1.1)'!D36,"F","R") -> F | E11: =IF('Coefficients (7.1.1)'!E49<'Coefficients (7.1.1)'!D49,"F","R") -> F | F11: =IF('Coefficients (7.1.1)'!E62<'Coefficients (7.1.1)'!D62,"F","R") -> R
B12: =IF('Coefficients (7.1.1)'!E12<'Coefficients (7.1.1)'!D12,"F","R") -> R | C12: =IF('Coefficients (7.1.1)'!E25<'Coefficients (7.1.1)'!D25,"F","R") -> R | D12: =IF('Coefficients (7.1.1)'!E38<'Coefficients (7.1.1)'!D38,"F","R") -> F | E12: =IF('Coefficients (7.1.1)'!E51<'Coefficients (7.1.1)'!D51,"F","R") -> F | F12: =IF('Coefficients (7.1.1)'!E64<'Coefficients (7.1.1)'!D64,"F","R") -> F
A13: POLST | B13: =IF('Coefficients (7.1.1)'!G4<'Coefficients (7.1.1)'!F4,"F","R") -> R | C13: =IF('Coefficients (7.1.1)'!G17<'Coefficients (7.1.1)'!F17,"F","R") -> F | D13: =IF('Coefficients (7.1.1)'!G30<'Coefficients (7.1.1)'!F30,"F","R") -> F | E13: =IF('Coefficients (7.1.1)'!G43<'Coefficients (7.1.1)'!F43,"F","R") -> F | F13: =IF('Coefficients (7.1.1)'!G56<'Coefficients (7.1.1)'!F56,"F","R") -> F
B14: =IF('Coefficients (7.1.1)'!G6<'Coefficients (7.1.1)'!F6,"F","R") -> R | C14: =IF('Coefficients (7.1.1)'!G19<'Coefficients (7.1.1)'!F19,"F","R") -> R | D14: =IF('Coefficients (7.1.1)'!G32<'Coefficients (7.1.1)'!F32,"F","R") -> R | E14: =IF('Coefficients (7.1.1)'!G45<'Coefficients (7.1.1)'!F45,"F","R") -> R | F14: =IF('Coefficients (7.1.1)'!G58<'Coefficients (7.1.1)'!F58,"F","R") -> R
B15: =IF('Coefficients (7.1.1)'!G8<'Coefficients (7.1.1)'!F8,"F","R") -> R | C15: =IF('Coefficients (7.1.1)'!G21<'Coefficients (7.1.1)'!F21,"F","R") -> F | D15: =IF('Coefficients (7.1.1)'!G34<'Coefficients (7.1.1)'!F34,"F","R") -> F | E15: =IF('Coefficients (7.1.1)'!G47<'Coefficients (7.1.1)'!F47,"F","R") -> F | F15: =IF('Coefficients (7.1.1)'!G60<'Coefficients (7.1.1)'!F60,"F","R") -> F
B16: =IF('Coefficients (7.1.1)'!G10<'Coefficients (7.1.1)'!F10,"F","R") -> R | C16: =IF('Coefficients (7.1.1)'!G23<'Coefficients (7.1.1)'!F23,"F","R") -> R | D16: =IF('Coefficients (7.1.1)'!G36<'Coefficients (7.1.1)'!F36,"F","R") -> R | E16: =IF('Coefficients (7.1.1)'!G49<'Coefficients (7.1.1)'!F49,"F","R") -> R | F16: =IF('Coefficients (7.1.1)'!G62<'Coefficients (7.1.1)'!F62,"F","R") -> R
B17: =IF('Coefficients (7.1.1)'!G12<'Coefficients (7.1.1)'!F12,"F","R") -> R | C17: =IF('Coefficients (7.1.1)'!G25<'Coefficients (7.1.1)'!F25,"F","R") -> F | D17: =IF('Coefficients (7.1.1)'!G38<'Coefficients (7.1.1)'!F38,"F","R") -> R | E17: =IF('Coefficients (7.1.1)'!G51<'Coefficients (7.1.1)'!F51,"F","R") -> F | F17: =IF('Coefficients (7.1.1)'!G64<'Coefficients (7.1.1)'!F64,"F","R") -> R
A18: REG | B18: =IF('Coefficients (7.1.1)'!I4<'Coefficients (7.1.1)'!H4,"F","R") -> R | C18: =IF('Coefficients (7.1.1)'!I17<'Coefficients (7.1.1)'!H17,"F","R") -> F | D18: =IF('Coefficients (7.1.1)'!I30<'Coefficients (7.1.1)'!H30,"F","R") -> F | E18: =IF('Coefficients (7.1.1)'!I43<'Coefficients (7.1.1)'!H43,"F","R") -> F | F18: =IF('Coefficients (7.1.1)'!I56<'Coefficients (7.1.1)'!H56,"F","R") -> F
B19: =IF('Coefficients (7.1.1)'!I6<'Coefficients (7.1.1)'!H6,"F","R") -> F | C19: =IF('Coefficients (7.1.1)'!I19<'Coefficients (7.1.1)'!H19,"F","R") -> R | D19: =IF('Coefficients (7.1.1)'!I32<'Coefficients (7.1.1)'!H32,"F","R") -> R | E19: =IF('Coefficients (7.1.1)'!I45<'Coefficients (7.1.1)'!H45,"F","R") -> F | F19: =IF('Coefficients (7.1.1)'!I58<'Coefficients (7.1.1)'!H58,"F","R") -> F
B20: =IF('Coefficients (7.1.1)'!I8<'Coefficients (7.1.1)'!H8,"F","R") -> R | C20: =IF('Coefficients (7.1.1)'!I21<'Coefficients (7.1.1)'!H21,"F","R") -> F | D20: =IF('Coefficients (7.1.1)'!I34<'Coefficients (7.1.1)'!H34,"F","R") -> F | E20: =IF('Coefficients (7.1.1)'!I47<'Coefficients (7.1.1)'!H47,"F","R") -> R | F20: =IF('Coefficients (7.1.1)'!I60<'Coefficients (7.1.1)'!H60,"F","R") -> F
B21: =IF('Coefficients (7.1.1)'!I10<'Coefficients (7.1.1)'!H10,"F","R") -> R | C21: =IF('Coefficients (7.1.1)'!I23<'Coefficients (7.1.1)'!H23,"F","R") -> R | D21: =IF('Coefficients (7.1.1)'!I36<'Coefficients (7.1.1)'!H36,"F","R") -> R | E21: =IF('Coefficients (7.1.1)'!I49<'Coefficients (7.1.1)'!H49,"F","R") -> R | F21: =IF('Coefficients (7.1.1)'!I62<'Coefficients (7.1.1)'!H62,"F","R") -> R
B22: =IF('Coefficients (7.1.1)'!I12<'Coefficients (7.1.1)'!H12,"F","R") -> R | C22: =IF('Coefficients (7.1.1)'!I25<'Coefficients (7.1.1)'!H25,"F","R") -> R | D22: =IF('Coefficients (7.1.1)'!I38<'Coefficients (7.1.1)'!H38,"F","R") -> R | E22: =IF('Coefficients (7.1.1)'!I51<'Coefficients (7.1.1)'!H51,"F","R") -> F | F22: =IF('Coefficients (7.1.1)'!I64<'Coefficients (7.1.1)'!H64,"F","R") -> R
A23: RULE | B23: =IF('Coefficients (7.1.1)'!K4<'Coefficients (7.1.1)'!J4,"F","R") -> F | C23: =IF('Coefficients (7.1.1)'!K17<'Coefficients (7.1.1)'!J17,"F","R") -> F | D23: =IF('Coefficients (7.1.1)'!K30<'Coefficients (7.1.1)'!J30,"F","R") -> R | E23: =IF('Coefficients (7.1.1)'!K43<'Coefficients (7.1.1)'!J43,"F","R") -> F | F23: =IF('Coefficients (7.1.1)'!K56<'Coefficients (7.1.1)'!J56,"F","R") -> F
B24: =IF('Coefficients (7.1.1)'!K6<'Coefficients (7.1.1)'!J6,"F","R") -> R | C24: =IF('Coefficients (7.1.1)'!K19<'Coefficients (7.1.1)'!J19,"F","R") -> R | D24: =IF('Coefficients (7.1.1)'!K32<'Coefficients (7.1.1)'!J32,"F","R") -> R | E24: =IF('Coefficients (7.1.1)'!K45<'Coefficients (7.1.1)'!J45,"F","R") -> F | F24: =IF('Coefficients (7.1.1)'!K58<'Coefficients (7.1.1)'!J58,"F","R") -> R
B25: =IF('Coefficients (7.1.1)'!K8<'Coefficients (7.1.1)'!J8,"F","R") -> F | C25: =IF('Coefficients (7.1.1)'!K21<'Coefficients (7.1.1)'!J21,"F","R") -> F | D25: =IF('Coefficients (7.1.1)'!K34<'Coefficients (7.1.1)'!J34,"F","R") -> R | E25: =IF('Coefficients (7.1.1)'!K47<'Coefficients (7.1.1)'!J47,"F","R") -> F | F25: =IF('Coefficients (7.1.1)'!K60<'Coefficients (7.1.1)'!J60,"F","R") -> F
B26: =IF('Coefficients (7.1.1)'!K10<'Coefficients (7.1.1)'!J10,"F","R") -> R | C26: =IF('Coefficients (7.1.1)'!K23<'Coefficients (7.1.1)'!J23,"F","R") -> R | D26: =IF('Coefficients (7.1.1)'!K36<'Coefficients (7.1.1)'!J36,"F","R") -> R | E26: =IF('Coefficients (7.1.1)'!K49<'Coefficients (7.1.1)'!J49,"F","R") -> R | F26: =IF('Coefficients (7.1.1)'!K62<'Coefficients (7.1.1)'!J62,"F","R") -> R
B27: =IF('Coefficients (7.1.1)'!K12<'Coefficients (7.1.1)'!J12,"F","R") -> F | C27: =IF('Coefficients (7.1.1)'!K25<'Coefficients (7.1.1)'!J25,"F","R") -> R | D27: =IF('Coefficients (7.1.1)'!K38<'Coefficients (7.1.1)'!J38,"F","R") -> R | E27: =IF('Coefficients (7.1.1)'!K51<'Coefficients (7.1.1)'!J51,"F","R") -> R | F27: =IF('Coefficients (7.1.1)'!K64<'Coefficients (7.1.1)'!J64,"F","R") -> R
A28: VOICE | B28: =IF('Coefficients (7.1.1)'!M4<'Coefficients (7.1.1)'!L4,"F","R") -> R | C28: =IF('Coefficients (7.1.1)'!M17<'Coefficients (7.1.1)'!L17,"F","R") -> F | D28: =IF('Coefficients (7.1.1)'!M30<'Coefficients (7.1.1)'!L30,"F","R") -> R | E28: =IF('Coefficients (7.1.1)'!M43<'Coefficients (7.1.1)'!L43,"F","R") -> F | F28: =IF('Coefficients (7.1.1)'!M56<'Coefficients (7.1.1)'!L56,"F","R") -> F
B29: =IF('Coefficients (7.1.1)'!M6<'Coefficients (7.1.1)'!L6,"F","R") -> R | C29: =IF('Coefficients (7.1.1)'!M19<'Coefficients (7.1.1)'!L19,"F","R") -> R | D29: =IF('Coefficients (7.1.1)'!M32<'Coefficients (7.1.1)'!L32,"F","R") -> R | E29: =IF('Coefficients (7.1.1)'!M45<'Coefficients (7.1.1)'!L45,"F","R") -> R | F29: =IF('Coefficients (7.1.1)'!M58<'Coefficients (7.1.1)'!L58,"F","R") -> R
B30: =IF('Coefficients (7.1.1)'!M8<'Coefficients (7.1.1)'!L8,"F","R") -> F | C30: =IF('Coefficients (7.1.1)'!M21<'Coefficients (7.1.1)'!L21,"F","R") -> F | D30: =IF('Coefficients (7.1.1)'!M34<'Coefficients (7.1.1)'!L34,"F","R") -> R | E30: =IF('Coefficients (7.1.1)'!M47<'Coefficients (7.1.1)'!L47,"F","R") -> F | F30: =IF('Coefficients (7.1.1)'!M60<'Coefficients (7.1.1)'!L60,"F","R") -> F
B31: =IF('Coefficients (7.1.1)'!M10<'Coefficients (7.1.1)'!L10,"F","R") -> R | C31: =IF('Coefficients (7.1.1)'!M23<'Coefficients (7.1.1)'!L23,"F","R") -> R | D31: =IF('Coefficients (7.1.1)'!M36<'Coefficients (7.1.1)'!L36,"F","R") -> R | E31: =IF('Coefficients (7.1.1)'!M49<'Coefficients (7.1.1)'!L49,"F","R") -> R | F31: =IF('Coefficients (7.1.1)'!M62<'Coefficients (7.1.1)'!L62,"F","R") -> R
B32: =IF('Coefficients (7.1.1)'!M12<'Coefficients (7.1.1)'!L12,"F","R") -> R | C32: =IF('Coefficients (7.1.1)'!M25<'Coefficients (7.1.1)'!L25,"F","R") -> R | D32: =IF('Coefficients (7.1.1)'!M38<'Coefficients (7.1.1)'!L38,"F","R") -> R | E32: =IF('Coefficients (7.1.1)'!M51<'Coefficients (7.1.1)'!L51,"F","R") -> R | F32: =IF('Coefficients (7.1.1)'!M64<'Coefficients (7.1.1)'!L64,"F","R") -> R
B35: Fall in Impact | C35: Rise in Impact
A36: Electricity Generation | B36: =(COUNTIF(B3:F3,"F")+COUNTIF(B8:F8,"F")+COUNTIF(B13:F13,"F")+COUNTIF(B18:F18,"F")+COUNTIF(B23:F23,"F")+COUNTIF(B28:F28,"F"))/30 -> 0.76666667 | C36: =(COUNTIF(B3:F3,"R")+COUNTIF(B8:F8,"R")+COUNTIF(B13:F13,"R")+COUNTIF(B18:F18,"R")+COUNTIF(B23:F23,"R")+COUNTIF(B28:F28,"R"))/30 -> 0.23333333
A37: Financial Access | B37: =(COUNTIF(B4:F4,"F")+COUNTIF(B9:F9,"F")+COUNTIF(B14:F14,"F")+COUNTIF(B19:F19,"F")+COUNTIF(B24:F24,"F")+COUNTIF(B29:F29,"F"))/30 -> 0.26666667 | C37: =(COUNTIF(B4:F4,"R")+COUNTIF(B9:F9,"R")+COUNTIF(B14:F14,"R")+COUNTIF(B19:F19,"R")+COUNTIF(B24:F24,"R")+COUNTIF(B29:F29,"R"))/30 -> 0.73333333
A38: Rural Population Growth | B38: =(COUNTIF(B5:F5,"F")+COUNTIF(B10:F10,"F")+COUNTIF(B15:F15,"F")+COUNTIF(B20:F20,"F")+COUNTIF(B25:F25,"F")+COUNTIF(B30:F30,"F"))/30 -> 0.6 | C38: =(COUNTIF(B5:F5,"R")+COUNTIF(B10:F10,"R")+COUNTIF(B15:F15,"R")+COUNTIF(B20:F20,"R")+COUNTIF(B25:F25,"R")+COUNTIF(B30:F30,"R"))/30 -> 0.4
A39: Income Inequality | B39: =(COUNTIF(B6:F6,"F")+COUNTIF(B11:F11,"F")+COUNTIF(B16:F16,"F")+COUNTIF(B21:F21,"F")+COUNTIF(B26:F26,"F")+COUNTIF(B31:F31,"F"))/30 -> 0.1 | C39: =(COUNTIF(B6:F6,"R")+COUNTIF(B11:F11,"R")+COUNTIF(B16:F16,"R")+COUNTIF(B21:F21,"R")+COUNTIF(B26:F26,"R")+COUNTIF(B31:F31,"R"))/30 -> 0.9
A40: Health Expenditure | B40: =(COUNTIF(B7:F7,"F")+COUNTIF(B12:F12,"F")+COUNTIF(B17:F17,"F")+COUNTIF(B22:F22,"F")+COUNTIF(B27:F27,"F")+COUNTIF(B32:F32,"F"))/30 -> 0.36666667 | C40: =(COUNTIF(B7:F7,"R")+COUNTIF(B12:F12,"R")+COUNTIF(B17:F17,"R")+COUNTIF(B22:F22,"R")+COUNTIF(B27:F27,"R")+COUNTIF(B32:F32,"R"))/30 -> 0.63333333

Sheet Coefficients (7.3.1)
B1: 7.3.1
B2: Ecosystem Vulnerability
B3: CORR | D3: GOVEFF | F3: POLST | H3: REG | J3: RULE | L3: VOICE
A4: Policy Stringency | B4: -0.0198 | C4: 0.0288 | D4: -0.0379 | E4: -0.0113 | F4: -0.0408 | G4: 0.0354 | H4: -0.0419 | I4: -0.0101 | J4: -0.0202 | K4: 0.003 | L4: -0.014 | M4: -0.0293
B5: -0.0177 | C5: -0.0263 | D5: -0.0175 | E5: -0.0237 | F5: -0.0176 | G5: -0.0261 | H5: -0.018 | I5: -0.0226 | J5: -0.0172 | K5: -0.0247 | L5: -0.0164 | M5: -0.0258
A6: Environmental Innovation | B6: -0.0556 | C6: 0.046 | D6: -0.0527 | E6: -0.0615 | F6: -0.0779 | G6: -0.0476 | H6: -0.0772 | I6: 0.0117 | J6: -0.0658 | K6: 0.0404 | L6: 0.0072 | M6: 0.0128
B7: -0.0273 | C7: -0.04 | D7: -0.0259 | E7: -0.0426 | F7: -0.0253 | G7: -0.0373 | H7: -0.0275 | I7: -0.04 | J7: -0.0248 | K7: -0.0424 | L7: -0.0229 | M7: -0.044
A8: Foreign Direct Investment | B8: -0.0232 | C8: -0.0087 | D8: -0.0489 | E8: -0.0682 | F8: -0.0471 | G8: -0.059 | H8: -0.0606 | I8: -0.0442 | J8: -0.0234 | K8: -0.0977 | L8: -0.0378 | M8: -0.0117
B9: -0.0364 | C9: -0.0609 | D9: -0.0394 | E9: -0.0513 | F9: -0.0381 | G9: -0.0536 | H9: -0.0408 | I9: -0.0487 | J9: -0.0391 | K9: -0.0545 | L9: -0.0353 | M9: -0.0509
A10: Industrial Share | B10: 0.4885 | C10: 1.2784 | D10: 0.7693 | E10: 0.8435 | F10: 0.6478 | G10: 1.1348 | H10: 0.8882 | I10: 0.9112 | J10: 0.515 | K10: 0.7839 | L10: 0.6023 | M10: 0.8026
B11: -0.1027 | C11: -0.1043 | D11: -0.0968 | E11: -0.1096 | F11: -0.0981 | G11: -0.1142 | H11: -0.0955 | I11: -0.1048 | J11: -0.0971 | K11: -0.0978 | L11: -0.0848 | M11: -0.1151
A12: Energy Demand | B12: -0.0625 | C12: -0.2552 | D12: -0.0322 | E12: 0.0258 | F12: 0.0142 | G12: -0.0462 | H12: -0.0027 | I12: -0.093 | J12: -0.0828 | K12: -0.0434 | L12: -0.2718 | M12: -0.1964
B13: -0.0472 | C13: -0.0666 | D13: -0.0408 | E13: -0.0611 | F13: -0.0417 | G13: -0.0575 | H13: -0.0459 | I13: -0.063 | J13: -0.0392 | K13: -0.0638 | L13: -0.0512 | M13: -0.0867
B15: Food Vulnerability
B16: CORR | D16: GOVEFF | F16: POLST | H16: REG | J16: RULE | L16: VOICE
A17: Policy Stringency | B17: -0.0301 | C17: -0.0061 | D17: -0.0455 | E17: -0.0433 | F17: -0.039 | G17: -0.0211 | H17: -0.0519 | I17: -0.0321 | J17: -0.0397 | K17: -0.0329 | L17: -0.0163 | M17: -0.0154
B18: -0.0166 | C18: -0.0163 | D18: -0.0165 | E18: -0.0204 | F18: -0.0169 | G18: -0.0226 | H18: -0.0163 | I18: -0.0189 | J18: -0.0157 | K18: -0.0197 | L18: -0.0151 | M18: -0.0189
A19: Environmental Innovation | B19: -0.047 | C19: 0.0226 | D19: -0.0423 | E19: -0.0538 | F19: -0.0753 | G19: -0.079 | H19: -0.0535 | I19: -0.0586 | J19: -0.0289 | K19: -0.0449 | L19: -0.0027 | M19: 0.0177
B20: -0.0251 | C20: -0.0332 | D20: -0.0238 | E20: -0.0365 | F20: -0.0242 | G20: -0.0287 | H20: -0.0235 | I20: -0.0356 | J20: -0.0227 | K20: -0.0287 | L20: -0.0214 | M20: -0.0357
A21: Financial Development | B21: -0.0133 | C21: -0.0184 | D21: -0.0238 | E21: -0.1033 | F21: -0.0414 | G21: -0.0823 | H21: -0.0263 | I21: -0.062 | J21: -0.02 | K21: -0.0639 | L21: -0.0199 | M21: -0.0002
B22: -0.0375 | C22: -0.0499 | D22: -0.0387 | E22: -0.0412 | F22: -0.0385 | G22: -0.0525 | H22: -0.0379 | I22: -0.0427 | J22: -0.0389 | K22: -0.0528 | L22: -0.0355 | M22: -0.0551
A23: Net Energy Import | B23: 0.7038 | C23: 1.2775 | D23: 0.6968 | E23: 0.779 | F23: 0.7174 | G23: 1.1427 | H23: 0.7238 | I23: 0.9755 | J23: 0.6868 | K23: 0.6792 | L23: 0.6655 | M23: 0.757
B24: -0.0872 | C24: -0.0786 | D24: -0.0833 | E24: -0.1081 | F24: -0.0885 | G24: -0.1006 | H24: -0.0825 | I24: -0.0915 | J24: -0.0819 | K24: -0.0908 | L24: -0.0778 | M24: -0.0965
A25: Low Carbon Trade | B25: -0.057 | C25: -0.2788 | D25: -0.0573 | E25: -0.0537 | F25: -0.012 | G25: -0.0765 | H25: -0.0334 | I25: -0.0866 | J25: -0.0867 | K25: -0.0701 | L25: -0.236 | M25: -0.274
B26: -0.0435 | C26: -0.0621 | D26: -0.0363 | E26: -0.0607 | F26: -0.0413 | G26: -0.0479 | H26: -0.0381 | I26: -0.0588 | J26: -0.0354 | K26: -0.0522 | L26: -0.0468 | M26: -0.074
B28: Health Vulnerability
B29: CORR | D29: GOVEFF | F29: POLST | H29: REG | J29: RULE | L29: VOICE
A30: Policy Stringency | B30: -0.0393 | C30: 0.0114 | D30: -0.0502 | E30: -0.0541 | F30: -0.0429 | G30: -0.0125 | H30: -0.0586 | I30: -0.0505 | J30: -0.0481 | K30: -0.0365 | L30: -0.022 | M30: -0.0279
B31: -0.0176 | C31: -0.0214 | D31: -0.0177 | E31: -0.0203 | F31: -0.0178 | G31: -0.0221 | H31: -0.0175 | I31: -0.0213 | J31: -0.0169 | K31: -0.0251 | L31: -0.0158 | M31: -0.0208
A32: Environmental Innovation | B32: -0.0631 | C32: -0.0182 | D32: -0.057 | E32: -0.0996 | F32: -0.0909 | G32: -0.1064 | H32: -0.0688 | I32: -0.0698 | J32: -0.0413 | K32: -0.0444 | L32: 0.0004 | M32: -0.0289
B33: -0.0261 | C33: -0.0352 | D33: -0.0251 | E33: -0.0338 | F33: -0.0255 | G33: -0.0254 | H33: -0.0252 | I33: -0.0359 | J33: -0.0244 | K33: -0.0358 | L33: -0.0225 | M33: -0.0376
A34: Financial Development | B34: -0.0132 | C34: -0.0524 | D34: -0.0236 | E34: -0.0926 | F34: -0.0333 | G34: -0.0717 | H34: -0.0207 | I34: -0.069 | J34: -0.0227 | K34: -0.1939 | L34: -0.0142 | M34: -0.0201
B35: -0.0396 | C35: -0.0564 | D35: -0.0417 | E35: -0.0456 | F35: -0.0404 | G35: -0.0495 | H35: -0.0395 | I35: -0.0467 | J35: -0.0414 | K35: -0.0589 | L35: -0.0366 | M35: -0.0485
A36: Net Energy Import | B36: 0.7932 | C36: 1.3091 | D36: 0.7645 | E36: 0.8585 | F36: 0.7638 | G36: 1.2722 | H36: 0.7486 | I36: 0.998 | J36: 0.7721 | K36: 0.921 | L36: 0.6422 | M36: 0.6714
B37: -0.0905 | C37: -0.0972 | D37: -0.0884 | E37: -0.098 | F37: -0.0942 | G37: -0.0906 | H37: -0.0878 | I37: -0.1002 | J37: -0.087 | K37: -0.0967 | L37: -0.0804 | M37: -0.1022
A38: Low Carbon Trade | B38: -0.033 | C38: -0.2055 | D38: -0.0345 | E38: 0.0435 | F38: 0.0127 | G38: -0.0146 | H38: -0.0047 | I38: -0.0307 | J38: -0.0685 | K38: -0.0601 | L38: -0.2442 | M38: -0.1224
